<?xml version="1.0"?>
<robot name="wx250s">

  <!-- =========================
       Link: wx250s/base_link
       ========================= -->
  <link name="wx250s/base_link">
    <visual>
      <!-- rpy="0 0 pi/2" -> "0 0 1.5708" -->
      <origin rpy="0 0 1.5708" xyz="0 0 0"/>
      <geometry>
        <mesh filename="package://wx-250s/meshes/wx250s_1_base.stl"
              scale="0.001 0.001 0.001"/>
      </geometry>
      <material name="interbotix_black"/>
    </visual>
    <collision>
      <origin rpy="0 0 1.5708" xyz="0 0 0"/>
      <geometry>
        <mesh filename="package://wx-250s/meshes/wx250s_1_base.stl"
              scale="0.001 0.001 0.001"/>
      </geometry>
    </collision>
    <inertial>
      <!-- rpy="0 0 pi/2" -> "0 0 1.5708" -->
      <origin rpy="0 0 1.5708" xyz="-0.0380446 0.000613892 0.0193354"/>
      <mass value="0.538736"/>
      <inertia ixx="0.002115"
               iyy="0.0006921"
               izz="0.002524"
               ixy="-0.00001635"
               ixz="0.0000006998"
               iyz="0.00004642"/>
    </inertial>
  </link>

  <!-- =========================
       Joint: waist
       ========================= -->
  <joint name="waist" type="revolute">
    <axis xyz="0 0 1"/>
    <!-- -pi + 0.00001 ~ -3.14158, pi - 0.00001 ~ 3.14158 -->
    <limit effort="10" lower="-3.14158" upper="3.14158" velocity="3.14159"/>
    <origin rpy="0 0 0" xyz="0 0 0.072"/>
    <parent link="wx250s/base_link"/>
    <child link="wx250s/shoulder_link"/>
    <dynamics friction="0.1"/>
  </joint>

  <!-- =========================
       Link: wx250s/shoulder_link
       ========================= -->
  <link name="wx250s/shoulder_link">
    <visual>
      <!-- rpy="0 0 pi/2" -> "0 0 1.5708" -->
      <origin rpy="0 0 1.5708" xyz="0 0 -0.003"/>
      <geometry>
        <mesh filename="package://wx-250s/meshes/wx250s_2_shoulder.stl"
              scale="0.001 0.001 0.001"/>
      </geometry>
      <material name="interbotix_black"/>
    </visual>
    <collision>
      <origin rpy="0 0 1.5708" xyz="0 0 -0.003"/>
      <geometry>
        <mesh filename="package://wx-250s/meshes/wx250s_2_shoulder.stl"
              scale="0.001 0.001 0.001"/>
      </geometry>
    </collision>
    <inertial>
      <!-- rpy="0 0 pi/2" -> "0 0 1.5708" -->
      <origin rpy="0 0 1.5708" xyz="0.0000223482 0.0000414609 0.0066287"/>
      <mass value="0.480879"/>
      <inertia ixx="0.000379"
               iyy="0.0005557"
               izz="0.0005889"
               ixy="0.0000000022"
               ixz="-0.0000003561"
               iyz="0.0000012245"/>
    </inertial>
  </link>

  <!-- =========================
       Joint: shoulder
       ========================= -->
  <joint name="shoulder" type="revolute">
    <axis xyz="0 1 0"/>
    <!-- radians(-108) ~ -1.88496, radians(114) ~ 1.98968 -->
    <limit effort="20" lower="-1.88496" upper="1.98968" velocity="3.14159"/>
    <origin rpy="0 0 0" xyz="0 0 0.03865"/>
    <parent link="wx250s/shoulder_link"/>
    <child link="wx250s/upper_arm_link"/>
    <dynamics friction="0.1"/>
  </joint>

  <!-- =========================
       Link: wx250s/upper_arm_link
       ========================= -->
  <link name="wx250s/upper_arm_link">
    <visual>
      <!-- rpy="0 0 pi/2" -> "0 0 1.5708" -->
      <origin rpy="0 0 1.5708" xyz="0 0 0"/>
      <geometry>
        <mesh filename="package://wx-250s/meshes/wx250s_3_upper_arm.stl"
              scale="0.001 0.001 0.001"/>
      </geometry>
      <material name="interbotix_black"/>
    </visual>
    <collision>
      <origin rpy="0 0 1.5708" xyz="0 0 0"/>
      <geometry>
        <mesh filename="package://wx-250s/meshes/wx250s_3_upper_arm.stl"
              scale="0.001 0.001 0.001"/>
      </geometry>
    </collision>
    <inertial>
      <!-- rpy="0 0 pi/2" -> "0 0 1.5708" -->
      <origin rpy="0 0 1.5708" xyz="0.0171605 0.0000002725 0.191323"/>
      <mass value="0.430811"/>
      <inertia ixx="0.003463"
               iyy="0.003587"
               izz="0.0004566"
               ixy="-0.0000000001"
               ixz="-0.0000000002"
               iyz="0.0004272"/>
    </inertial>
  </link>

  <!-- =========================
       Joint: elbow
       ========================= -->
  <joint name="elbow" type="revolute">
    <axis xyz="0 1 0"/>
    <!-- radians(-123) ~ -2.14675, radians(92) ~ 1.6057 -->
    <limit effort="15" lower="-2.14675" upper="1.60570" velocity="3.14159"/>
    <origin rpy="0 0 0" xyz="0.04975 0 0.25"/>
    <parent link="wx250s/upper_arm_link"/>
    <child link="wx250s/upper_forearm_link"/>
    <dynamics friction="0.1"/>
  </joint>

  <!-- =========================
       Link: wx250s/upper_forearm_link
       ========================= -->
  <link name="wx250s/upper_forearm_link">
    <visual>
      <origin rpy="0 0 0" xyz="0 0 0"/>
      <geometry>
        <mesh filename="package://wx-250s/meshes/wx250s_4_upper_forearm.stl"
              scale="0.001 0.001 0.001"/>
      </geometry>
      <material name="interbotix_black"/>
    </visual>
    <collision>
      <origin rpy="0 0 0" xyz="0 0 0"/>
      <geometry>
        <mesh filename="package://wx-250s/meshes/wx250s_4_upper_forearm.stl"
              scale="0.001 0.001 0.001"/>
      </geometry>
    </collision>
    <inertial>
      <origin rpy="0 0 0" xyz="0.107963 0.000115876 0"/>
      <mass value="0.234589"/>
      <inertia ixx="0.00003971"
               iyy="0.0008878"
               izz="0.000888"
               ixy="0.0000023528"
               ixz="0"
               iyz="0"/>
    </inertial>
  </link>

  <!-- =========================
       Joint: forearm_roll
       ========================= -->
  <joint name="forearm_roll" type="revolute">
    <axis xyz="1 0 0"/>
    <!-- -pi + 0.00001 ~ -3.14158, pi - 0.00001 ~ 3.14158 -->
    <limit effort="2" lower="-3.14158" upper="3.14158" velocity="3.14159"/>
    <origin rpy="0 0 0" xyz="0.175 0 0"/>
    <parent link="wx250s/upper_forearm_link"/>
    <child link="wx250s/lower_forearm_link"/>
    <dynamics friction="0.1"/>
  </joint>

  <!-- =========================
       Link: wx250s/lower_forearm_link
       ========================= -->
  <link name="wx250s/lower_forearm_link">
    <visual>
      <!-- rpy="pi 0 0" -> "3.14159 0 0" -->
      <origin rpy="3.14159 0 0" xyz="0 0 0"/>
      <geometry>
        <mesh filename="package://wx-250s/meshes/wx250s_5_lower_forearm.stl"
              scale="0.001 0.001 0.001"/>
      </geometry>
      <material name="interbotix_black"/>
    </visual>
    <collision>
      <origin rpy="3.14159 0 0" xyz="0 0 0"/>
      <geometry>
        <mesh filename="package://wx-250s/meshes/wx250s_5_lower_forearm.stl"
              scale="0.001 0.001 0.001"/>
      </geometry>
    </collision>
    <inertial>
      <origin rpy="3.14159 0 0" xyz="0.0374395 0.00522252 0"/>
      <mass value="0.220991"/>
      <inertia ixx="0.00006369"
               iyy="0.0001677"
               izz="0.0001834"
               ixy="-0.00002292"
               ixz="0"
               iyz="0"/>
    </inertial>
  </link>

  <!-- =========================
       Joint: wrist_angle
       ========================= -->
  <joint name="wrist_angle" type="revolute">
    <axis xyz="0 1 0"/>
    <!-- radians(-100) ~ -1.74533, radians(123) ~ 2.14675 -->
    <limit effort="5" lower="-1.74533" upper="2.14675" velocity="3.14159"/>
    <origin rpy="0 0 0" xyz="0.075 0 0"/>
    <parent link="wx250s/lower_forearm_link"/>
    <child link="wx250s/wrist_link"/>
    <dynamics friction="0.1"/>
  </joint>

  <!-- =========================
       Link: wx250s/wrist_link
       ========================= -->
  <link name="wx250s/wrist_link">
    <visual>
      <!-- rpy="0 0 pi/2" -> "0 0 1.5708" -->
      <origin rpy="0 0 1.5708" xyz="0 0 0"/>
      <geometry>
        <mesh filename="package://wx-250s/meshes/wx250s_6_wrist.stl"
              scale="0.001 0.001 0.001"/>
      </geometry>
      <material name="interbotix_black"/>
    </visual>
    <collision>
      <origin rpy="0 0 1.5708" xyz="0 0 0"/>
      <geometry>
        <mesh filename="package://wx-250s/meshes/wx250s_6_wrist.stl"
              scale="0.001 0.001 0.001"/>
      </geometry>
    </collision>
    <inertial>
      <origin rpy="0 0 1.5708" xyz="0.04236 -0.000010663 0.010577"/>
      <mass value="0.084957"/>
      <inertia ixx="0.00003082"
               iyy="0.00002822"
               izz="0.00003152"
               ixy="0.0000000191"
               ixz="0.0000000023"
               iyz="0.0000025481"/>
    </inertial>
  </link>

  <!-- =========================
       Joint: wrist_rotate
       ========================= -->
  <joint name="wrist_rotate" type="revolute">
    <axis xyz="1 0 0"/>
    <!-- -pi + 0.00001 ~ -3.14158, pi - 0.00001 ~ 3.14158 -->
    <limit effort="1" lower="-3.14158" upper="3.14158" velocity="3.14159"/>
    <origin rpy="0 0 0" xyz="0.065 0 0"/>
    <parent link="wx250s/wrist_link"/>
    <child link="wx250s/gripper_link"/>
    <dynamics friction="0.1"/>
  </joint>

  <!-- =========================
       Link: wx250s/gripper_link
       ========================= -->
  <link name="wx250s/gripper_link">
    <visual>
      <!-- rpy="0 0 pi/2" -> "0 0 1.5708" -->
      <origin rpy="0 0 1.5708" xyz="-0.02 0 0"/>
      <geometry>
        <mesh filename="package://wx-250s/meshes/wx250s_7_gripper.stl"
              scale="0.001 0.001 0.001"/>
      </geometry>
      <material name="interbotix_black"/>
    </visual>
    <collision>
      <origin rpy="0 0 1.5708" xyz="-0.02 0 0"/>
      <geometry>
        <mesh filename="package://wx-250s/meshes/wx250s_7_gripper.stl"
              scale="0.001 0.001 0.001"/>
      </geometry>
    </collision>
    <inertial>
      <origin rpy="0 0 1.5708" xyz="0.021631 0.0000002516 0.01141"/>
      <mass value="0.072885"/>
      <inertia ixx="0.00002537"
               iyy="0.00001836"
               izz="0.00001674"
               ixy="0"
               ixz="0"
               iyz="0.000000434"/>
    </inertial>
  </link>

  <!-- =========================
       Joint: ee_arm (fixed)
       ========================= -->
  <joint name="ee_arm" type="fixed">
    <axis xyz="1 0 0"/>
    <origin rpy="0 0 0" xyz="0.043 0 0"/>
    <parent link="wx250s/gripper_link"/>
    <child link="wx250s/ee_arm_link"/>
  </joint>

  <!-- =========================
       Link: wx250s/ee_arm_link
       ========================= -->
  <link name="wx250s/ee_arm_link">
    <inertial>
      <origin rpy="0 0 0" xyz="0 0 0"/>
      <mass value="0.001"/>
      <inertia ixx="0.001" iyy="0.001" izz="0.001" ixy="0" ixz="0" iyz="0"/>
    </inertial>
  </link>

  <!-- =========================
       Joint: gripper (continuous)
       ========================= -->
  <joint name="gripper" type="revolute">
    <axis xyz="1 0 0"/>
    <limit effort="1" velocity="3.14159"/>
    <origin rpy="0 0 0" xyz="0.0055 0 0"/>
    <parent link="wx250s/ee_arm_link"/>
    <child link="wx250s/gripper_prop_link"/>
    <dynamics friction="0.1"/>
  </joint>

  <!-- =========================
       Link: wx250s/gripper_prop_link
       ========================= -->
  <link name="wx250s/gripper_prop_link">
    <visual>
      <!-- rpy="0 0 pi/2" -> "0 0 1.5708" -->
      <origin rpy="0 0 1.5708" xyz="-0.0685 0 0"/>
      <geometry>
        <mesh filename="package://wx-250s/meshes/wx250s_8_gripper_prop.stl"
              scale="0.001 0.001 0.001"/>
      </geometry>
      <material name="interbotix_black"/>
    </visual>
    <collision>
      <origin rpy="0 0 1.5708" xyz="-0.0685 0 0"/>
      <geometry>
        <mesh filename="package://wx-250s/meshes/wx250s_8_gripper_prop.stl"
              scale="0.001 0.001 0.001"/>
      </geometry>
    </collision>
    <inertial>
      <origin rpy="0 0 1.5708" xyz="0.000846 -0.0000016817 0.000042"/>
      <mass value="0.00434"/>
      <inertia ixx="0.0000005923"
               iyy="0.0000011156"
               izz="0.0000005743"
               ixy="0"
               ixz="0.0000003195"
               iyz="-0.0000000004"/>
    </inertial>
  </link>

  <!-- =========================
       Because show_gripper_bar=true
       ========================= -->
  <joint name="gripper_bar" type="fixed">
    <axis xyz="1 0 0"/>
    <origin rpy="0 0 0" xyz="0 0 0"/>
    <parent link="wx250s/ee_arm_link"/>
    <child link="wx250s/gripper_bar_link"/>
  </joint>

  <link name="wx250s/gripper_bar_link">
    <visual>
      <!-- rpy="0 0 pi/2" -> "0 0 1.5708" -->
      <origin rpy="0 0 1.5708" xyz="-0.063 0 0"/>
      <geometry>
        <mesh filename="package://wx-250s/meshes/wx250s_9_gripper_bar.stl"
              scale="0.001 0.001 0.001"/>
      </geometry>
      <material name="interbotix_black"/>
    </visual>
    <collision>
      <origin rpy="0 0 1.5708" xyz="-0.063 0 0"/>
      <geometry>
        <mesh filename="package://wx-250s/meshes/wx250s_9_gripper_bar.stl"
              scale="0.001 0.001 0.001"/>
      </geometry>
    </collision>
    <inertial>
      <origin rpy="0 0 1.5708" xyz="0.009687 0.0000008177 0.004962"/>
      <mass value="0.034199"/>
      <inertia ixx="0.0000074125"
               iyy="0.00002843"
               izz="0.00002860"
               ixy="-0.0000000008"
               ixz="-0.0000000006"
               iyz="-0.0000013889"/>
    </inertial>
  </link>

  <joint name="ee_bar" type="fixed">
    <axis xyz="1 0 0"/>
    <origin rpy="0 0 0" xyz="0.023 0 0"/>
    <parent link="wx250s/gripper_bar_link"/>
    <child link="wx250s/fingers_link"/>
  </joint>

  <link name="wx250s/fingers_link">
    <inertial>
      <origin rpy="0 0 0" xyz="0 0 0"/>
      <mass value="0.001"/>
      <inertia ixx="0.001" iyy="0.001" izz="0.001" ixy="0" ixz="0" iyz="0"/>
    </inertial>
  </link>

  <!-- =========================
       Because show_gripper_fingers=true
       ========================= -->

    <joint name="left_finger" type="fixed">
      <axis xyz="0 1 0"/>
      <limit effort="5" lower="0.015" upper="0.037" velocity="1"/>
      <origin rpy="0 0 0" xyz="0 0 0"/>
      <parent link="wx250s/fingers_link"/>
      <child link="wx250s/left_finger_link"/>
      <dynamics friction="0.1"/>
      <mimic joint="gripper" multiplier="-1.0" offset="0.015"/>
    </joint>

  <link name="wx250s/left_finger_link">
    <!-- rpy="${pi} ${pi} 0" -> "3.14159 3.14159 0" but effectively flips mesh -->
    <visual>
      <origin rpy="3.14159 3.14159 0" xyz="0 0.005 0"/>
      <geometry>
        <mesh filename="package://wx-250s/meshes/wx250s_10_gripper_finger.stl"
              scale="0.001 0.001 0.001"/>
      </geometry>
      <material name="interbotix_black"/>
    </visual>
    <collision>
      <origin rpy="3.14159 3.14159 0" xyz="0 0.005 0"/>
      <geometry>
        <mesh filename="package://wx-250s/meshes/wx250s_10_gripper_finger.stl"
              scale="0.001 0.001 0.001"/>
      </geometry>
    </collision>
    <inertial>
      <!-- rpy="${pi} ${pi} ${pi/2}" -> "3.14159 3.14159 1.5708" -->
      <origin rpy="3.14159 3.14159 1.5708" xyz="0.013816 0 0"/>
      <mass value="0.016246"/>
      <inertia ixx="0.0000047310"
               iyy="0.0000015506"
               izz="0.0000037467"
               ixy="-0.0000004560"
               ixz="0"
               iyz="0"/>
    </inertial>
  </link>

  <!-- Right finger -->
  <joint name="right_finger" type="fixed">
    <axis xyz="0 1 0"/>
    <!-- lower=-0.037, upper=-0.015 -->
    <limit effort="5" lower="-0.037" upper="-0.015" velocity="1"/>
    <origin rpy="0 0 0" xyz="0 0 0"/>
    <parent link="wx250s/fingers_link"/>
    <child link="wx250s/right_finger_link"/>
    <dynamics friction="0.1"/>
    <!-- Because load_gazebo_configs=false, we mimic left_finger -->
    <mimic joint="left_finger" multiplier="-1" offset="0"/>
  </joint>

  <link name="wx250s/right_finger_link">
    <visual>
      <!-- rpy="0 pi 0" -> "0 3.14159 0" flips the mesh -->
      <origin rpy="0 3.14159 0" xyz="0 -0.005 0"/>
      <geometry>
        <mesh filename="package://wx-250s/meshes/wx250s_10_gripper_finger.stl"
              scale="0.001 0.001 0.001"/>
      </geometry>
      <material name="interbotix_black"/>
    </visual>
    <collision>
      <origin rpy="0 3.14159 0" xyz="0 -0.005 0"/>
      <geometry>
        <mesh filename="package://wx-250s/meshes/wx250s_10_gripper_finger.stl"
              scale="0.001 0.001 0.001"/>
      </geometry>
    </collision>
    <inertial>
      <!-- rpy="0 pi pi/2" -> "0 3.14159 1.5708" -->
      <origin rpy="0 3.14159 1.5708" xyz="0.013816 0 0"/>
      <mass value="0.016246"/>
      <inertia ixx="0.0000047310"
               iyy="0.0000015506"
               izz="0.0000037467"
               ixy="0.0000004560"
               ixz="0"
               iyz="0"/>
    </inertial>
  </link>

  <!-- Fixed joint after the fingers -->
  <joint name="ee_gripper" type="fixed">
    <axis xyz="1 0 0"/>
    <origin rpy="0 0 0" xyz="0.027575 0 0"/>
    <parent link="wx250s/fingers_link"/>
    <child link="wx250s/ee_gripper_link"/>
  </joint>

  <link name="wx250s/ee_gripper_link">
    <inertial>
      <origin rpy="0 0 0" xyz="0 0 0"/>
      <mass value="0.001"/>
      <inertia ixx="0.001" iyy="0.001" izz="0.001" ixy="0" ixz="0" iyz="0"/>
    </inertial>
  </link>

</robot>
